
Inference time: 63.4
{"AutoencoderKL": "type", "DiffusionPipeline": "type", "EulerDiscreteScheduler": "type", "PIL": "module", "config": "Config", "get_ipython": "function", "image": "Tensor", "image_processor": "module", "inference_scheduler": "EulerDiscreteScheduler", "latent": "StableDiffusionXLPipelineOutput", "list": "list", "new_img": "Image", "np": "module", "os": "module", "pipe": "StableDiffusionXLPipeline", "refined_image": "list", "refiner": "StableDiffusionXLImg2ImgPipeline", "start_time": "float", "time": "module", "torch": "module", "vae": "AutoencoderKL", "wandb": "module"}
{"AutoencoderKL": "type", "DiffusionPipeline": "type", "EulerDiscreteScheduler": "type", "PIL": "module", "config": "Config", "get_ipython": "function", "image": "Tensor", "image_processor": "module", "inference_scheduler": "EulerDiscreteScheduler", "latent": "StableDiffusionXLPipelineOutput", "list": "list", "new_img": "Image", "np": "module", "os": "module", "pipe": "StableDiffusionXLPipeline", "refined_image": "list", "refiner": "StableDiffusionXLImg2ImgPipeline", "start_time": "float", "time": "module", "torch": "module", "vae": "AutoencoderKL", "wandb": "module"}
{"AutoencoderKL": "type", "DiffusionPipeline": "type", "EulerDiscreteScheduler": "type", "PIL": "module", "config": "Config", "get_ipython": "function", "image": "Tensor", "image_processor": "module", "inference_scheduler": "EulerDiscreteScheduler", "latent": "StableDiffusionXLPipelineOutput", "list": "list", "new_img": "Image", "np": "module", "os": "module", "pipe": "StableDiffusionXLPipeline", "refined_image": "list", "refiner": "StableDiffusionXLImg2ImgPipeline", "start_time": "float", "time": "module", "torch": "module", "vae": "AutoencoderKL", "wandb": "module"}
{"shape": "(4, 3, 1024, 1024)", "count": 4, "type": "Tensor"}
{"shape": "(4, 3, 1024, 1024)", "count": 4, "type": "Tensor"}
{"shape": "(4, 3, 1024, 1024)", "count": 4, "type": "Tensor"}
Exception in thread SockSrvRdThr:
Traceback (most recent call last):
  File "/home/ray/anaconda3/lib/python3.10/threading.py", line 1016, in _bootstrap_inner
    self.run()
  File "/home/ray/anaconda3/lib/python3.10/site-packages/wandb/sdk/service/server_sock.py", line 99, in run
    sreq = self._sock_client.read_server_request()
  File "/home/ray/anaconda3/lib/python3.10/site-packages/wandb/sdk/lib/sock_client.py", line 274, in read_server_request
    data = self._read_packet_bytes()
  File "/home/ray/anaconda3/lib/python3.10/site-packages/wandb/sdk/lib/sock_client.py", line 248, in _read_packet_bytes
    rec = self._extract_packet_bytes()
  File "/home/ray/anaconda3/lib/python3.10/site-packages/wandb/sdk/lib/sock_client.py", line 230, in _extract_packet_bytes
    assert magic == ord("W")
AssertionError
Exception in thread SockSrvRdThr:
Traceback (most recent call last):
  File "/home/ray/anaconda3/lib/python3.10/threading.py", line 1016, in _bootstrap_inner
    self.run()
  File "/home/ray/anaconda3/lib/python3.10/site-packages/wandb/sdk/service/server_sock.py", line 99, in run
    sreq = self._sock_client.read_server_request()
  File "/home/ray/anaconda3/lib/python3.10/site-packages/wandb/sdk/lib/sock_client.py", line 274, in read_server_request
    data = self._read_packet_bytes()
  File "/home/ray/anaconda3/lib/python3.10/site-packages/wandb/sdk/lib/sock_client.py", line 248, in _read_packet_bytes
    rec = self._extract_packet_bytes()
  File "/home/ray/anaconda3/lib/python3.10/site-packages/wandb/sdk/lib/sock_client.py", line 230, in _extract_packet_bytes
    assert magic == ord("W")
AssertionError